Workbook

Sheet 1人あたりのシミュレーション
C2: 東京都
C3: 項目 | D3: 値
C4: 現在の月額支給額「額面） | D4: 300000 | E4: ← 要入力
C5: 賃料 | D5: 80000
C6: 都道府県 | D6: 東京都
C8: ■ 結果（自動） | D8: 制度利用前 | E8: 制度利用時
C9: 項目 | D9: 値 | E9: 値
C10: 月収（額面） | D10: =round(D4/10000,1) -> 30 | E10: =round((D4-D5*0.8)/10000,1) -> 23.6
C11: 税金・社保 | D11: =D10-round('制度未利用の手取り'!H10/10000,1) -> 6.1 | E11: =E10-round('制度利用時の手取り'!H10/10000,1) -> 4.7
C12: 家賃 | D12: =round(D5/10000,1) -> 8 | E12: =round(D5*0.2/10000,1) -> 1.6
C13: 実質手取り（制度未利用時） | D13: =round('制度未利用の手取り'!H11/10000,1) -> 15.9 | E13: =round('制度利用時の手取り'!H11/10000,1) -> 17.3
C14: 月実質手取り増加 | E14: =round('制度利用時の手取り'!H11-'制度未利用の手取り'!H11,0) -> 14240
C15: 年実質手取り増加 | E15: =E14*12 -> 170880
C16: 家賃減額 | E16: =round(D5*0.8/10000,1) -> 6.4
C18: 詳細 | D18: 値 | E18: 体
C19: 月収 | D19: =D4 -> 300000 | E19: =D4-D5*0.8 -> 236000
C20: 社会保険料 | D20: =round('制度未利用の手取り'!H18/12,1) -> 44115 | E20: =round('制度利用時の手取り'!H18/12,1) -> 35268
C21: 住民税 | D21: =round('制度未利用の手取り'!H42/12,1) -> 12755.2 | E21: =round('制度利用時の手取り'!H42/12,1) -> 9159.8
C22: 所得税 | D22: =round('制度未利用の手取り'!H52/12,1) -> 4294.3 | E22: =round('制度利用時の手取り'!H52/12,1) -> 2496.6
C23: 家賃 | D23: =D5 -> 80000 | E23: =D5*0.2 -> 16000

Sheet 制度未利用の手取り
B2: 入力
C3: 額面月額支給 | H3: ='1人あたりのシミュレーション'!D4 -> 300000
C4: 賞与額 | H4: 0
C5: 支給回数 | H5: 1
C6: 家賃 | H6: ='1人あたりのシミュレーション'!D5 -> 80000
C7: 減額割合 | H7: 0
B9: 効果
C10: 手取り月額 | H10: =H14/12 -> 238835.58
C11: 実質手取り月額 | H11: =H13/12 -> 158835.58
C12: 社保
B13: 実質手取年総額 | H13: =H14-H59 -> 1906027
B14: 手取年総額 | H14: =H15-H17 -> 2866027
C15: 年間給与収入 | H15: =H16*12+H4*H5 -> 3600000
D16: 額面月額支給 | H16: =H3-H6*H7 -> 300000
C17: 控除総額 | H17: =H18+H42+H52 -> 733973
D18: 社会保険料 | H18: =H19*12+H29 -> 529380 | I18: =H18/12 -> 44115
E19: 社会保険料 - 月額分 | H19: =H20+H23+H26 -> 44115
F20: 健康保険 - 月額分 | H20: =IFERROR(__xludf.DUMMYFUNCTION("ROUND(if(H21>=H22,'定数'!G96, filter('定数'!$G$47:$G$96,'定数'!$C$47:$C$96=H21)))"),14865.0) -> 14865
G21: 標準報酬月額 | H21: =IFERROR(__xludf.DUMMYFUNCTION("filter('定数'!$C$47:$C$96,'定数'!$D$47:$D$96<=H16,'定数'!$E$47:$E$96>H16)"),300000.0) -> 300000
G22: 月額上限 | H22: ='定数'!$E$4 -> 1390000
F23: 厚生年金保険 - 月額分 | H23: =IFERROR(__xludf.DUMMYFUNCTION("ROUND(if(H24>=H25,'定数'!$I$96,filter('定数'!$I$47:$I$96,'定数'!$C$47:$C$96=H21)))"),27450.0) -> 27450
G24: 標準報酬月額 | H24: =H21 -> 300000
G25: 月額上限 | H25: ='定数'!$E$5 -> 650000
F26: 雇用保険 - 月額分 | H26: =H16*'定数'!$F$6 -> 1800
G27: 額面月額支給 | H27: =H16 -> 300000
G28: 雇用保険料率 | H28: ='定数'!$F$6 -> 0.006
E29: 社会保険料 - 賞与分 | H29: =H30+H34+H39 -> 0
F30: 健康保険 - 賞与分 | H30: =if(H32>=H33,H33*H31,H31*H32) -> 0
G31: 健康保険料率 | H31: ='定数'!$F$4*(1-'定数'!$G$4) -> 0.0495
G32: 総支給賞与額 | H32: =H4*H5 -> 0
G33: 賞与総額上限 | H33: ='定数'!$I$4 -> 5730000
F34: 厚生年金保険 - 賞与分 | H34: =if(H36/H38>=H37,H37*H35*H38,H36*H35) -> 0
G35: 厚生年金保険料率 | H35: ='定数'!$F$5*(1-'定数'!$G$5) -> 0.0915
G36: 総支給賞与額 | H36: =H32 -> 0
G37: 支給毎の賞与上限 | H37: ='定数'!$I$5 -> 1500000
G38: 支給回数 | H38: =H5 -> 1
F39: 雇用保険 - 賞与分 | H39: =H40*H41 -> 0
G40: 雇用保険料率 | H40: =H28 -> 0.006
G41: 総支給賞与額 | H41: =H32 -> 0
D42: 住民税額 | H42: =round(H43*H50+H51,0) -> 153062 | I42: =H42/12 -> 12755.167
...

Sheet 制度利用時の手取り
B2: 入力
C3: 額面月額支給 | H3: ='1人あたりのシミュレーション'!D4 -> 300000
C4: 賞与額 | H4: 0
C5: 支給回数 | H5: 1
C6: 家賃 | H6: ='1人あたりのシミュレーション'!D5 -> 80000
C7: 減額割合 | H7: 0.8
B9: 効果
C10: 手取り月額 | H10: =H14/12 -> 189075.57
C11: 実質手取り月額 | H11: =H13/12 -> 173075.57
B13: 実質手取年総額 | H13: =H14-H59 -> 2076906.8
B14: 手取年総額 | H14: =H15-H17 -> 2268906.8
C15: 年間給与収入 | H15: =H16*12+H4*H5 -> 2832000
D16: 額面月額支給 | H16: =H3-H6*H7 -> 236000
C17: 控除総額 | H17: =H18+H42+H52 -> 563093.2
D18: 社会保険料 | H18: =H19*12+H29 -> 423216 | I18: =H18/12 -> 35268
E19: 社会保険料 - 月額分 | H19: =H20+H23+H26 -> 35268
F20: 健康保険 - 月額分 | H20: =IFERROR(__xludf.DUMMYFUNCTION("ROUND(if(H21>=H22,'定数'!G96, filter('定数'!$G$47:$G$96,'定数'!$C$47:$C$96=H21)))"),11892.0) -> 11892
G21: 標準報酬月額 | H21: =IFERROR(__xludf.DUMMYFUNCTION("filter('定数'!$C$47:$C$96,'定数'!$D$47:$D$96<=H16,'定数'!$E$47:$E$96>H16)"),240000.0) -> 240000
G22: 月額上限 | H22: ='定数'!$E$4 -> 1390000
F23: 厚生年金保険 - 月額分 | H23: =IFERROR(__xludf.DUMMYFUNCTION("ROUND(if(H24>=H25,'定数'!$I$96,filter('定数'!$I$47:$I$96,'定数'!$C$47:$C$96=H21)))"),21960.0) -> 21960
G24: 標準報酬月額 | H24: =H21 -> 240000
G25: 月額上限 | H25: ='定数'!$E$5 -> 650000
F26: 雇用保険 - 月額分 | H26: =H16*'定数'!$F$6 -> 1416
G27: 額面月額支給 | H27: =H16 -> 236000
G28: 雇用保険料率 | H28: ='定数'!$F$6 -> 0.006
E29: 社会保険料 - 賞与分 | H29: =H30+H34+H39 -> 0
F30: 健康保険 - 賞与分 | H30: =if(H32>=H33,H33*H31,H31*H32) -> 0
G31: 健康保険料率 | H31: ='定数'!$F$4*(1-'定数'!$G$4) -> 0.0495
G32: 総支給賞与額 | H32: =H4*H5 -> 0
G33: 賞与総額上限 | H33: ='定数'!$I$4 -> 5730000
F34: 厚生年金保険 - 賞与分 | H34: =if(H36/H38>=H37,H37*H35*H38,H36*H35) -> 0
G35: 厚生年金保険料率 | H35: ='定数'!$F$5*(1-'定数'!$G$5) -> 0.0915
G36: 総支給賞与額 | H36: =H32 -> 0
G37: 支給毎の賞与上限 | H37: ='定数'!$I$5 -> 1500000
G38: 支給回数 | H38: =H5 -> 1
F39: 雇用保険 - 賞与分 | H39: =H40*H41 -> 0
G40: 雇用保険料率 | H40: =H28 -> 0.006
G41: 総支給賞与額 | H41: =H32 -> 0
D42: 住民税額 | H42: =round(H43*H50+H51,0) -> 109918
E43: 年間課税所得 - 住民税 | H43: =H44-H48-H49 -> 1049184
...

Sheet 定数
B2: 社会保険料
D3: 課税対象 | E3: 対象上限 | F3: 保険料率 | G3: 会社負担率 | H3: 上限額 | I3: 賞与上限
C4: 健康保険 | D4: 標準報酬月額 | E4: 1390000 | F4: 0.099 | G4: 0.5 | H4: =E4*F4*(1-G4) -> 68805 | I4: 5730000
C5: 厚生年金保険 | D5: 標準報酬月額 | E5: 650000 | F5: 0.183 | G5: 0.5 | H5: =E5*F5*(1-G5) -> 59475 | I5: 1500000
C6: 雇用保険 | D6: 当月の総支給額 | F6: 0.006 | H6: 0
B8: 税金 | D8: 課税対象 | E8: 均等割 | F8: 対象割合 | G8: 基礎控除
C9: 住民税 | D9: 前年の課税所得 | E9: 5000 | F9: 0.1 | G9: 430000
C10: 所得税 | D10: 毎月の給与額 | E10: 0 | F10: 累進課税 | G10: 累進
B12: 所得税率
C13: 課税される所得金額 | E13: 税率 | F13: 控除額
C14: から | D14: まで
C15: 1000 | D15: 1949000 | E15: 0.05 | F15: 0
C16: 1950000 | D16: 3299000 | E16: 0.1 | F16: 97500
C17: 3300000 | D17: 6949000 | E17: 0.2 | F17: 427500
C18: 6950000 | D18: 8999000 | E18: 0.23 | F18: 636000
C19: 9000000 | D19: 17999000 | E19: 0.33 | F19: 1536000
C20: 18000000 | D20: 39999000 | E20: 0.4 | F20: 2796000
C21: 40000000 | E21: 0.45 | F21: 4796000
B23: 給与所得控除
C24: 給与等の収入金額 (給与所得の源泉徴収票の支払金額) | E24: 均等割 | F24: 所得割
C25: から | D25: まで
C26: 0 | D26: 1900000 | E26: 650000 | F26: 0
C27: 1900000 | D27: 3600000 | E27: 80000 | F27: 0.3
C28: 3600000 | D28: 6600000 | E28: 440000 | F28: 0.2
C29: 6600000 | D29: 8500000 | E29: 1100000 | F29: 0.1
C30: 8500000 | E30: 1950000 | F30: 0
B32: 基礎控除
C33: 所得（以上） | D33: 所得（未満） | E33: 令和7年分 令和8年分 | F33: 令和9年分 以後
C34: 0 | D34: 1320000 | E34: 950000 | F34: 950000
C35: 1320000 | D35: =C36 -> 3360000 | E35: 880000 | F35: 580000
C36: 3360000 | D36: =C37 -> 4890000 | E36: 680000 | F36: 580000
C37: 4890000 | D37: =C38 -> 6550000 | E37: 630000 | F37: 580000
C38: 6550000 | D38: =C39 -> 23500000 | E38: 580000 | F38: 580000
C39: 23500000 | D39: =C40 -> 24000000 | E39: 480000 | F39: 480000
C40: 24000000 | D40: =C41 -> 24500000 | E40: 320000 | F40: 320000
C41: 24500000 | D41: =C42 -> 25000000 | E41: 160000 | F41: 160000
C42: 25000000 | E42: 0 | F42: 0
B44: 標準報酬月額
C45: 標準報酬月額 | D45: 報酬月額(以上) | E45: 報酬月額(未満) | F45: 健康保険 | H45: 厚生年金保険
F46: 全額（円） | G46: 折半額（円） | H46: 全額（円） | I46: 折半額（円）
...
